2019-07-04 12:35:11,808 ERROR: Exception on /rfilog/1 [GET] [in d:\files\greg\personal\hobbies\python\rfi_webapp\venv\lib\site-packages\flask\app.py:1780]
Traceback (most recent call last):
  File "d:\files\greg\personal\hobbies\python\rfi_webapp\venv\lib\site-packages\flask\app.py", line 2311, in wsgi_app
    response = self.full_dispatch_request()
  File "d:\files\greg\personal\hobbies\python\rfi_webapp\venv\lib\site-packages\flask\app.py", line 1834, in full_dispatch_request
    rv = self.handle_user_exception(e)
  File "d:\files\greg\personal\hobbies\python\rfi_webapp\venv\lib\site-packages\flask\app.py", line 1737, in handle_user_exception
    reraise(exc_type, exc_value, tb)
  File "d:\files\greg\personal\hobbies\python\rfi_webapp\venv\lib\site-packages\flask\_compat.py", line 36, in reraise
    raise value
  File "d:\files\greg\personal\hobbies\python\rfi_webapp\venv\lib\site-packages\flask\app.py", line 1832, in full_dispatch_request
    rv = self.dispatch_request()
  File "d:\files\greg\personal\hobbies\python\rfi_webapp\venv\lib\site-packages\flask\app.py", line 1818, in dispatch_request
    return self.view_functions[rule.endpoint](**req.view_args)
  File "d:\files\greg\personal\hobbies\python\rfi_webapp\venv\lib\site-packages\flask_login\utils.py", line 261, in decorated_view
    return func(*args, **kwargs)
  File "D:\Files\Greg\Personal\Hobbies\Python\RFI_WebApp\app\routes.py", line 91, in rfilog
    return render_template('RFI_Log.html', title='RFI Log', rfis=rfis, project=project)
  File "d:\files\greg\personal\hobbies\python\rfi_webapp\venv\lib\site-packages\flask\templating.py", line 135, in render_template
    context, ctx.app)
  File "d:\files\greg\personal\hobbies\python\rfi_webapp\venv\lib\site-packages\flask\templating.py", line 117, in _render
    rv = template.render(context)
  File "d:\files\greg\personal\hobbies\python\rfi_webapp\venv\lib\site-packages\jinja2\asyncsupport.py", line 76, in render
    return original_render(self, *args, **kwargs)
  File "d:\files\greg\personal\hobbies\python\rfi_webapp\venv\lib\site-packages\jinja2\environment.py", line 1008, in render
    return self.environment.handle_exception(exc_info, True)
  File "d:\files\greg\personal\hobbies\python\rfi_webapp\venv\lib\site-packages\jinja2\environment.py", line 780, in handle_exception
    reraise(exc_type, exc_value, tb)
  File "d:\files\greg\personal\hobbies\python\rfi_webapp\venv\lib\site-packages\jinja2\_compat.py", line 37, in reraise
    raise value.with_traceback(tb)
  File "D:\Files\Greg\Personal\Hobbies\Python\RFI_WebApp\app\templates\RFI_Log.html", line 1, in top-level template code
    {% extends 'base.html' %}
  File "D:\Files\Greg\Personal\Hobbies\Python\RFI_WebApp\app\templates\base.html", line 40, in top-level template code
    {% block content %}{% endblock %}
  File "D:\Files\Greg\Personal\Hobbies\Python\RFI_WebApp\app\templates\RFI_Log.html", line 25, in block "content"
    <td><a href="{{ url_for('RFI_Resp', rfi_number=rfi.rfi_number) }}">{{ rfi.rfi_number }}</a></td>
  File "d:\files\greg\personal\hobbies\python\rfi_webapp\venv\lib\site-packages\flask\helpers.py", line 356, in url_for
    return appctx.app.handle_url_build_error(error, endpoint, values)
  File "d:\files\greg\personal\hobbies\python\rfi_webapp\venv\lib\site-packages\flask\app.py", line 2080, in handle_url_build_error
    reraise(exc_type, exc_value, tb)
  File "d:\files\greg\personal\hobbies\python\rfi_webapp\venv\lib\site-packages\flask\_compat.py", line 36, in reraise
    raise value
  File "d:\files\greg\personal\hobbies\python\rfi_webapp\venv\lib\site-packages\flask\helpers.py", line 345, in url_for
    force_external=external)
  File "d:\files\greg\personal\hobbies\python\rfi_webapp\venv\lib\site-packages\werkzeug\routing.py", line 2007, in build
    raise BuildError(endpoint, values, method, self)
werkzeug.routing.BuildError: Could not build url for endpoint 'RFI_Resp' with values ['rfi_number']. Did you forget to specify values ['id']?
2019-07-04 12:38:01,068 INFO: RFIWebApp Startup [in D:\Files\Greg\Personal\Hobbies\Python\RFI_WebApp\app\__init__.py:44]
2019-07-04 12:38:47,931 ERROR: Exception on /rfilog/1 [GET] [in d:\files\greg\personal\hobbies\python\rfi_webapp\venv\lib\site-packages\flask\app.py:1780]
Traceback (most recent call last):
  File "d:\files\greg\personal\hobbies\python\rfi_webapp\venv\lib\site-packages\flask\app.py", line 2311, in wsgi_app
    response = self.full_dispatch_request()
  File "d:\files\greg\personal\hobbies\python\rfi_webapp\venv\lib\site-packages\flask\app.py", line 1834, in full_dispatch_request
    rv = self.handle_user_exception(e)
  File "d:\files\greg\personal\hobbies\python\rfi_webapp\venv\lib\site-packages\flask\app.py", line 1737, in handle_user_exception
    reraise(exc_type, exc_value, tb)
  File "d:\files\greg\personal\hobbies\python\rfi_webapp\venv\lib\site-packages\flask\_compat.py", line 36, in reraise
    raise value
  File "d:\files\greg\personal\hobbies\python\rfi_webapp\venv\lib\site-packages\flask\app.py", line 1832, in full_dispatch_request
    rv = self.dispatch_request()
  File "d:\files\greg\personal\hobbies\python\rfi_webapp\venv\lib\site-packages\flask\app.py", line 1818, in dispatch_request
    return self.view_functions[rule.endpoint](**req.view_args)
  File "d:\files\greg\personal\hobbies\python\rfi_webapp\venv\lib\site-packages\flask_login\utils.py", line 261, in decorated_view
    return func(*args, **kwargs)
  File "D:\Files\Greg\Personal\Hobbies\Python\RFI_WebApp\app\routes.py", line 91, in rfilog
    return render_template('RFI_Log.html', title='RFI Log', rfis=rfis, project=project)
  File "d:\files\greg\personal\hobbies\python\rfi_webapp\venv\lib\site-packages\flask\templating.py", line 135, in render_template
    context, ctx.app)
  File "d:\files\greg\personal\hobbies\python\rfi_webapp\venv\lib\site-packages\flask\templating.py", line 117, in _render
    rv = template.render(context)
  File "d:\files\greg\personal\hobbies\python\rfi_webapp\venv\lib\site-packages\jinja2\asyncsupport.py", line 76, in render
    return original_render(self, *args, **kwargs)
  File "d:\files\greg\personal\hobbies\python\rfi_webapp\venv\lib\site-packages\jinja2\environment.py", line 1008, in render
    return self.environment.handle_exception(exc_info, True)
  File "d:\files\greg\personal\hobbies\python\rfi_webapp\venv\lib\site-packages\jinja2\environment.py", line 780, in handle_exception
    reraise(exc_type, exc_value, tb)
  File "d:\files\greg\personal\hobbies\python\rfi_webapp\venv\lib\site-packages\jinja2\_compat.py", line 37, in reraise
    raise value.with_traceback(tb)
  File "D:\Files\Greg\Personal\Hobbies\Python\RFI_WebApp\app\templates\RFI_Log.html", line 1, in top-level template code
    {% extends 'base.html' %}
  File "D:\Files\Greg\Personal\Hobbies\Python\RFI_WebApp\app\templates\base.html", line 40, in top-level template code
    {% block content %}{% endblock %}
  File "D:\Files\Greg\Personal\Hobbies\Python\RFI_WebApp\app\templates\RFI_Log.html", line 25, in block "content"
    <td><a href="{{ url_for('RFI_Resp', rfi_number=rfi.rfi_number) }}">{{ rfi.rfi_number }}</a></td>
  File "d:\files\greg\personal\hobbies\python\rfi_webapp\venv\lib\site-packages\flask\helpers.py", line 356, in url_for
    return appctx.app.handle_url_build_error(error, endpoint, values)
  File "d:\files\greg\personal\hobbies\python\rfi_webapp\venv\lib\site-packages\flask\app.py", line 2080, in handle_url_build_error
    reraise(exc_type, exc_value, tb)
  File "d:\files\greg\personal\hobbies\python\rfi_webapp\venv\lib\site-packages\flask\_compat.py", line 36, in reraise
    raise value
  File "d:\files\greg\personal\hobbies\python\rfi_webapp\venv\lib\site-packages\flask\helpers.py", line 345, in url_for
    force_external=external)
  File "d:\files\greg\personal\hobbies\python\rfi_webapp\venv\lib\site-packages\werkzeug\routing.py", line 2007, in build
    raise BuildError(endpoint, values, method, self)
werkzeug.routing.BuildError: Could not build url for endpoint 'RFI_Resp' with values ['rfi_number']. Did you forget to specify values ['id']?
2019-07-04 12:39:45,223 INFO: RFIWebApp Startup [in D:\Files\Greg\Personal\Hobbies\Python\RFI_WebApp\app\__init__.py:44]
2019-07-04 12:39:52,127 ERROR: Exception on /uploads/1/RFI3 - Third Sewer RFI.pdf [GET] [in d:\files\greg\personal\hobbies\python\rfi_webapp\venv\lib\site-packages\flask\app.py:1780]
Traceback (most recent call last):
  File "d:\files\greg\personal\hobbies\python\rfi_webapp\venv\lib\site-packages\flask\app.py", line 2311, in wsgi_app
    response = self.full_dispatch_request()
  File "d:\files\greg\personal\hobbies\python\rfi_webapp\venv\lib\site-packages\flask\app.py", line 1834, in full_dispatch_request
    rv = self.handle_user_exception(e)
  File "d:\files\greg\personal\hobbies\python\rfi_webapp\venv\lib\site-packages\flask\app.py", line 1737, in handle_user_exception
    reraise(exc_type, exc_value, tb)
  File "d:\files\greg\personal\hobbies\python\rfi_webapp\venv\lib\site-packages\flask\_compat.py", line 36, in reraise
    raise value
  File "d:\files\greg\personal\hobbies\python\rfi_webapp\venv\lib\site-packages\flask\app.py", line 1832, in full_dispatch_request
    rv = self.dispatch_request()
  File "d:\files\greg\personal\hobbies\python\rfi_webapp\venv\lib\site-packages\flask\app.py", line 1818, in dispatch_request
    return self.view_functions[rule.endpoint](**req.view_args)
TypeError: showfile() got an unexpected keyword argument 'id'
2019-07-04 12:44:18,641 INFO: RFIWebApp Startup [in D:\Files\Greg\Personal\Hobbies\Python\RFI_WebApp\app\__init__.py:44]
